Workbook

Sheet IS
A2: CONSOLIDATED STATEMENTS OF OPERATIONS
A6: (dollars in millions, except per share amounts) | C6: 2019 | D6: 2020 | E6: 2021
A7: Net sales:
A8: Product sales | C8: 5648 | D8: 5371 | E8: 6428
A9: Service sales | C9: 7470 | D9: 7385 | E9: 7870
C10: 13118 | D10: 12756 | E10: 14298
A11: Costs and expenses:
A12: Cost of products sold | C12: 4640 | D12: 4439 | E12: 5293
A13: Cost of services sold | C13: 4652 | D13: 4538 | E13: 4812
A14: Research and development | C14: 163 | D14: 152 | E14: 159
A15: Selling, general and administrative | C15: 1810 | D15: 1924 | E15: 1948
C16: 11265 | D16: 11053 | E16: 12212
A17: Other income (expense), net | C17: -39 | D17: -64 | E17: 22
A18: Operating profit | C18: 1814 | D18: 1639 | E18: 2108
A19: Non-service pension benefit (Cost) | C19: -33 | D19: 6 | E19: 11
A20: Interest income (expense), net | C20: -14 | D20: 122 | E20: 136
A21: Net income before income taxes | C21: 1861 | D21: 1511 | E21: 1961
A22: Income tax expense | C22: 594 | D22: 455 | E22: 541
A23: Net income | C23: 1267 | D23: 1056 | E23: 1420
A24: Less: Noncontrolling interest in subsidiaries' earnings | C24: 151 | D24: 150 | E24: 174
A33: Net income attributable to Otis | C33: 1116 | D33: 906 | E33: 1246
A37: Earnings per share (Note 3):
A39: Basic | C39: 2.55 | D39: 2.09 | E39: 2.91
A40: Diluted | C40: 2.55 | D40: 2.08 | E40: 2.89
A41: Weighted average number of shares outstanding
A42: Basic shares | C42: 433.1 | D42: 433.2 | E42: 427.7
A43: Diluted shares | C43: 433.1 | D43: 434.6 | E43: 431.4

Sheet BS
A2: CONSOLIDATED BALANCE SHEETS
A5: (dollars in millions) | D5: 2020 | E5: 2021
A6: Assets
A7: Cash and cash equivalents | D7: 1782 | E7: 1565
A8: Restricted cash | D8: 17 | E8: 1910
A9: Accounts receivable (net of allowance for expected credit losses of $175 and $161) | D9: 3148 | E9: 3232
A10: Contract assets | D10: 458 | E10: 550
A11: Inventories, net | D11: 659 | E11: 622
A12: Other current assets | D12: 429 | E12: 382
A13: Total Current Assets | D13: 6493 | E13: 8261
A14: Future income tax benefits | D14: 334 | E14: 335
A15: Fixed assets, net | D15: 774 | E15: 774
A16: Operating lease right-of-use assets | D16: 542 | E16: 526
A17: Intangible assets, net | D17: 484 | E17: 419
A18: Goodwill | D18: 1773 | E18: 1667
... A20: Total Assets | D20: 10710 | E20: 12279
A21: Liabilities and (Deficit) Equity
A22: Short-term borrowings | D22: 701 | E22: 24
A23: Accounts payable | D23: 1453 | E23: 1556
A24: Accrued liabilities | D24: 1977 | E24: 1993
A25: Contract liabilities | D25: 2542 | E25: 2674
A27: Total Current Liabilities | D27: 6673 | E27: 6247
A28: Long-term debt | D28: 5262 | E28: 7249
A29: Future pension and postretirement benefit obligations | D29: 654 | E29: 558
A30: Operating lease liabilities | D30: 367 | E30: 336
A31: Future income tax obligations | D31: 321 | E31: 267
A32: Other long-term liabilities | D32: 634 | E32: 606
A33: Total Liabilities | D33: 13911 | E33: 15263
A34: Commitments and contingent liabilities (Note 22)
A35: Redeemable noncontrolling interest | D35: 194 | E35: 160
A36: Shareholders' (Deficit) Equity:
A37: Common Stock and additional paid-in-capital | D37: 59 | E37: 119
A38: Treasury Stock | D38: — | E38: -725
A40: Accumulated deficit | D40: -3106 | E40: -2256
A42: Accumulated other comprehensive income (loss) | D42: -815 | E42: -763
A43: Total Shareholders' (Deficit) Equity | D43: -3862 | E43: -3625
A44: Noncontrolling interest | D44: 467 | E44: 481
A45: Total (Deficit) Equity | D45: -3395 | E45: -3144
A46: Total Liabilities and (Deficit) Equity | D46: 10710 | E46: 12279

Sheet CF
A2: CONSOLIDATED STATEMENTS OF CASH FLOWS
A5: (dollars in millions) | C5: 2019 | D5: 2020 | E5: 2021
A6: Operating Activities:
A7: Net income | C7: 1267 | D7: 1056 | E7: 1420
A8: Adjustments to reconcile net income to net cash flows provided by operating activities, net of acquisitions:
A9: Depreciation and amortization | C9: 180 | D9: 191 | E9: 203
A10: Deferred income tax expense (benefit) | C10: -8 | D10: -51 | E10: -92
A11: Stock compensation cost | C11: 37 | D11: 63 | E11: 65
A12: Losses on fixed asset impairment or disposal of business | C12: 26 | D12: 71 | E12: 0
A15: Change in:
A16: Accounts receivable, net | C16: -191 | D16: -163 | E16: -152
A17: Contract assets and liabilities, current | C17: 97 | D17: 282 | E17: 53
A18: Inventories, net | C18: 60 | D18: -76 | E18: 14
A19: Other current assets | C19: 30 | D19: 28 | E19: 43
A20: Accounts payable | C20: 6 | D20: 20 | E20: 130
A21: Accrued liabilities | C21: -34 | D21: -14 | E21: 72
A24: Pension contributions | C24: -32 | D24: -64 | E24: -37
A25: Other operating activities, net | C25: 31 | D25: 137 | E25: 31
A26: Net cash flows provided by operating activities | C26: 1469 | D26: 1480 | E26: 1750
A27: Investing Activities:
A28: Capital expenditures | C28: -145 | D28: -183 | E28: -156
A29: Investments in businesses and intangible assets, net of cash acquired (Note 9) | C29: -47 | D29: -53 | E29: -80
A30: Proceeds from sale of (investments in) equity securities | C30: 0 | D30: -51 | E30: 40
A32: Receipts (payments) on settlements of derivative contracts | C32: -5 | D32: -69 | E32: 73
A33: Other investing activities, net | C33: -6 | D33: 3 | E33: 34
A34: Net cash flows used in investing activities | C34: -203 | D34: -353 | E34: -89
A35: Financing Activities:
A36: Net proceeds from (repayments of) borrowings (maturities of 90 days or less) | C36: 6 | D36: 647 | E36: -304
A37: Proceeds from borrowings (maturities longer than 90 days) | C37: 0 | D37: 0 | E37: 152
A38: Repayments of borrowings (maturities longer than 90 days) | C38: 0 | D38: 0 | E38: -503
A39: Proceeds from issuance of long-term debt | C39: 0 | D39: 6300 | E39: 2030
A40: Payment of debt issuance costs | C40: 0 | D40: -43 | E40: -25
A41: Repayment of long-term debt | C41: 0 | D41: -1000 | E41: 0
A43: Dividends paid on Common Stock | C43: 0 | D43: -260 | E43: -393
A44: Repurchases of Common Stock | C44: 0 | D44: 0 | E44: -725
A45: Dividends paid to noncontrolling interest | C45: -163 | D45: -149 | E45: -155
A46: Net transfers to UTC | C46: -972 | D46: -6330 | E46: 0
A47: Other financing activities, net | C47: -4 | D47: -9 | E47: -19
A48: Net cash flows provided by (used in) financing activities | C48: -1133 | D48: -844 | E48: 58
... A55: Cash and cash equivalents, end of period | C55: 1446 | D55: 1782 | E55: 1565
...

Sheet MODEL
B1: Otis | D1: 2019 | E1: =D1+1 -> 2020 | F1: =E1+1 -> 2021 | G1: =F1+1 -> 2022 | H1: =G1+1 -> 2023 | I1: =H1+1 -> 2024 | J1: =I1+1 -> 2025 | K1: =J1+1 -> 2026
B3: Market Size | D3: =D40/D5 -> 35300 | E3: =E40/E5 -> 31594.118 | F3: =F40/F5 -> 35711.111 | G3: =F3*(1+G4) -> 37496.667 | H3: =G3*(1+H4) -> 39371.5 | I3: =H3*(1+I4) -> 41340.075 | J3: =I3*(1+J4) -> 43407.079 | K3: =J3*(1+K4) -> 45577.433
B4: Market Growth Rate | E4: =E3/D3-1 -> -0.1049825 | F4: =F3/E3-1 -> 0.13030886 | G4: 0.05 | H4: 0.05 | I4: 0.05 | J4: 0.05 | K4: 0.05
B5: Product Market Share | D5: 0.16 | E5: 0.17 | F5: 0.18 | G5: =F5 -> 0.18 | H5: =G5 -> 0.18 | I5: 0.182 | J5: 0.184 | K5: 0.186
B7: Service units | D7: 2 | E7: 2.1 | F7: 2.15 | G7: =F7*(1+G8) -> 2.2145 | H7: =G7*(1+H8) -> 2.280935 | I7: =H7*(1+I8) -> 2.351644 | J7: =I7*(1+J8) -> 2.4268966 | K7: =J7*(1+K8) -> 2.5069842
E8: =E7/D7-1 -> 0.05 | F8: =F7/E7-1 -> 0.023809524 | G8: 0.03 | H8: 0.03 | I8: 0.031 | J8: 0.032 | K8: 0.033
B10: Revenue Units | D10: =D41/D7 -> 3735 | E10: =E41/E7 -> 3516.6667 | F10: =F41/F7 -> 3660.4651 | G10: =F10*(1+G11) -> 3806.8837 | H10: =G10*(1+H11) -> 3940.1247 | I10: =H10*(1+I11) -> 4078.029 | J10: =I10*(1+J11) -> 4220.76 | K10: =J10*(1+K11) -> 4368.4866
E11: =E10/D10-1 -> -0.058456046 | F11: =F10/E10-1 -> 0.040890554 | G11: 0.04 | H11: 0.035 | I11: =H11 -> 0.035 | J11: =I11 -> 0.035 | K11: =J11 -> 0.035
B12: COPS as % of Product sales | D12: =D44/D40 -> -0.82152975 | E12: =E44/E40 -> -0.82647552 | F12: =F44/F40 -> -0.82342875 | G12: =AVERAGE(D12:F12) -> -0.82381134 | H12: =G12 -> -0.82381134 | I12: =H12 -> -0.82381134 | J12: =I12 -> -0.82381134 | K12: =J12 -> -0.82381134
B13: COSS as % of Services sales | D13: =D45/D41 -> -0.6227577 | E13: =E45/E41 -> -0.61448883 | F13: =F45/F41 -> -0.61143583 | G13: =AVERAGE(D13:F13) -> -0.61622745 | H13: =G13 -> -0.61622745 | I13: =H13 -> -0.61622745 | J13: =I13 -> -0.61622745 | K13: =J13 -> -0.61622745
B14: S&GA R&D as % of total revenue | D14: =D48/D42 -> -0.15040403 | E14: =E48/E42 -> -0.16274694 | F14: =F48/F42 -> -0.14736327 | G14: =AVERAGE(D14:F14) -> -0.15350475 | H14: =G14 -> -0.15350475 | I14: =H14 -> -0.15350475 | J14: =I14 -> -0.15350475 | K14: =J14 -> -0.15350475
B15: tax as % EBT | D15: =D58/D56 -> -0.31918323 | E15: =E58/E56 -> -0.30112508 | F15: =F58/F56 -> -0.27587965 | G15: =AVERAGE(D15:F15) -> -0.29872932 | H15: =G15 -> -0.29872932 | I15: =H15 -> -0.29872932 | J15: =I15 -> -0.29872932 | K15: =J15 -> -0.29872932
B16: NCI as % of NI | D16: =D61/D59 -> -0.11917916 | E16: =E61/E59 -> -0.14204545 | F16: =F61/F59 -> -0.12253521 | G16: =AVERAGE(D16:F16) -> -0.12791994 | H16: =G16 -> -0.12791994 | I16: =H16 -> -0.12791994 | J16: =I16 -> -0.12791994 | K16: =J16 -> -0.12791994
B17: Interest As % of Debt | E17: =E55/E79 -> -0.0204595 | F17: =F55/F79 -> -0.018699299 | G17: =AVERAGE(D17:F17) -> -0.0195794 | H17: =G17 -> -0.0195794 | I17: =H17 -> -0.0195794 | J17: =I17 -> -0.0195794 | K17: =J17 -> -0.0195794
B19: Total Expenses | E19: =E44+E45+E48 -> -11053 | F19: =F44+F45+F48 -> -12212 | G19: =G44+G45+G48 -> -13085.404 | H19: =H44+H45+H48 -> -13843.825 | I19: =I44+I45+I48 -> -14735.01 | J19: =J44+J45+J48 -> -15690.363 | K19: =K44+K45+K48 -> -16714.999
B20: Account Receivable as % Revenue | E20: =E68/E42 -> 0.24678583 | F20: =F68/F42 -> 0.2260456 | G20: =AVERAGE(E20:F20) -> 0.23641571 | H20: =G20 -> 0.23641571 | I20: =H20 -> 0.23641571 | J20: =I20 -> 0.23641571 | K20: =J20 -> 0.23641571
B21: Accounts payable as % Cog | E21: =E76/SUM(E44:E45) -> -0.16185808 | F21: =F76/SUM(F44:F45) -> -0.15398318 | G21: =AVERAGE(E21:F21) -> -0.15792063 | H21: =G21 -> -0.15792063 | I21: =H21 -> -0.15792063 | J21: =I21 -> -0.15792063 | K21: =J21 -> -0.15792063
B22: Accrued liabilities as % Total Expenses | E22: =E77/SUM(E44:E45,E48) -> -0.17886547 | F22: =F77/SUM(F44:F45,F48) -> -0.16320013 | G22: =AVERAGE(E22:F22) -> -0.1710328 | H22: =G22 -> -0.1710328 | I22: =H22 -> -0.1710328 | J22: =I22 -> -0.1710328 | K22: =J22 -> -0.1710328
B23: Contract liabilities as % of Total Expenses | E23: =E78/SUM(E44:E45,E48) -> -0.22998281 | F23: =F78/SUM(F44:F45,F48) -> -0.21896495 | G23: =AVERAGE(E23:F23) -> -0.22447388 | H23: =G23 -> -0.22447388 | I23: =H23 -> -0.22447388 | J23: =I23 -> -0.22447388 | K23: =J23 -> -0.22447388
B24: Inventory and Other Assets as % of COG | E24: =E69/SUM(E44:E45) -> -0.17221789 | F24: =F69/SUM(F44:F45) -> -0.15378525 | G24: =AVERAGE(E24:F24) -> -0.16300157 | H24: =G24 -> -0.16300157 | I24: =H24 -> -0.16300157 | J24: =I24 -> -0.16300157 | K24: =J24 -> -0.16300157
B25: Operating lease right-of-use assets as % Opex | E25: =E71/E48 -> -0.261079 | F25: =F71/F48 -> -0.24964404 | G25: =AVERAGE(E25:F25) -> -0.25536152 | H25: =G25 -> -0.25536152 | I25: =H25 -> -0.25536152 | J25: =I25 -> -0.25536152 | K25: =J25 -> -0.25536152
B26: Other Liabilities as % Total Expenses | E26: =E81/E19 -> -0.14557134 | F26: =F81/F19 -> -0.11717982 | G26: =AVERAGE(E26:F26) -> -0.13137558 | H26: =G26 -> -0.13137558 | I26: =H26 -> -0.13137558 | J26: =I26 -> -0.13137558 | K26: =J26 -> -0.13137558
B28: Depriciation as % total revenue | D28: =D94/D42 -> 0.013721604 | E28: =E94/E42 -> 0.014973346 | F28: =F94/F42 -> 0.01419779 | G28: =AVERAGE(D28:F28) -> 0.01429758 | H28: =G28 -> 0.01429758 | I28: =H28 -> 0.01429758 | J28: =I28 -> 0.01429758 | K28: =J28 -> 0.01429758
B29: Capex as % of total revenue | D29: =D100/D42 -> -0.011053514 | E29: =E100/E42 -> -0.01434619 | F29: =F100/F42 -> -0.010910617 | G29: =AVERAGE(D29:F29) -> -0.01210344 | H29: =G29 -> -0.01210344 | I29: =H29 -> -0.01210344 | J29: =I29 -> -0.01210344 | K29: =J29 -> -0.01210344
B30: Other Operating Activities As % of Rev | D30: =D97/D42 -> 0.0041164812 | E30: =E97/E42 -> 0.012229539 | F30: =F97/F42 -> -0.0023080151 | G30: =AVERAGE(D30:F30) -> 0.004679335 | H30: =G30 -> 0.004679335 | I30: =H30 -> 0.004679335 | J30: =I30 -> 0.004679335 | K30: =J30 -> 0.004679335
B31: Debt as Flat | E31: =E79 -> 5963 | F31: =F79 -> 7273 | G31: =F31 -> 7273 | H31: =G31 -> 7273 | I31: =H31 -> 7273 | J31: =I31 -> 7273 | K31: =J31 -> 7273
B32: Dividends on CS As % of NI | D32: =D105/D59 -> 0 | E32: =E105/E59 -> -0.24621212 | F32: =F105/F59 -> -0.27676056 | G32: =AVERAGE(D32:F32) -> -0.17432423 | H32: =AVERAGE(E32:G32) -> -0.2324323 | I32: =AVERAGE(F32:H32) -> -0.22783903 | J32: =AVERAGE(G32:I32) -> -0.21153185 | K32: =AVERAGE(H32:J32) -> -0.2239344
B33: No Repurchases of Common Stock | D33: 0 | E33: 0 | F33: 0 | G33: 0 | H33: 0 | I33: 0 | J33: 0 | K33: 0
B34: Dividends NCI as % of NCI Income | D34: =D107/D61 -> 1.0794702 | E34: =E107/E61 -> 0.99333333 | F34: =F107/F61 -> 0.8908046 | G34: =AVERAGE(D34:F34) -> 0.98786938 | H34: =G34 -> 0.98786938 | I34: =H34 -> 0.98786938 | J34: =I34 -> 0.98786938 | K34: =J34 -> 0.98786938
B35: Forex as % of Revenue | D35: =D110/D42 -> -0.0015246227 | E35: =E110/E42 -> 0.0046252744 | F35: =F110/F42 -> -0.0030074136 | G35: =AVERAGE(D35:F35) -> 3.1079367e-05 | H35: =G35 -> 3.1079367e-05 | I35: =H35 -> 3.1079367e-05 | J35: =I35 -> 3.1079367e-05 | K35: =J35 -> 3.1079367e-05
B36: Other Financing Activities As % of 0 | G36: 0 | H36: 0 | I36: 0 | J36: 0 | K36: 0
B38: Income Statement
B40: =IS!A8 -> Product sales | D40: =IS!C8 -> 5648 | E40: =IS!D8 -> 5371 | F40: =IS!E8 -> 6428 | G40: =G3*G5 -> 6749.4 | H40: =H3*H5 -> 7086.87 | I40: =I3*I5 -> 7523.8937 | J40: =J3*J5 -> 7986.9025 | K40: =K3*K5 -> 8477.4025
B41: =IS!A9 -> Service sales | D41: =IS!C9 -> 7470 | E41: =IS!D9 -> 7385 | F41: =IS!E9 -> 7870 | G41: =G10*G7 -> 8430.344 | H41: =H10*H7 -> 8987.1682 | I41: =I10*I7 -> 9590.0724 | J41: =J10*J7 -> 10243.348 | K41: =K10*K7 -> 10951.727
B42: Total Revenue | D42: =SUM(D40:D41) -> 13118 | E42: =SUM(E40:E41) -> 12756 | F42: =SUM(F40:F41) -> 14298 | G42: =SUM(G40:G41) -> 15179.744 | H42: =SUM(H40:H41) -> 16074.038 | I42: =SUM(I40:I41) -> 17113.966 | J42: =SUM(J40:J41) -> 18230.251 | K42: =SUM(K40:K41) -> 19429.129
B44: =IS!A12 -> Cost of products sold | D44: =-IS!C12 -> -4640 | E44: =-IS!D12 -> -4439 | F44: =-IS!E12 -> -5293 | G44: =G12*G40 -> -5560.2322 | H44: =H12*H40 -> -5838.2438 | I44: =I12*I40 -> -6198.2689 | J44: =J12*J40 -> -6579.7008 | K44: =K12*K40 -> -6983.7803
B45: =IS!A13 -> Cost of services sold | D45: =-IS!C13 -> -4652 | E45: =-IS!D13 -> -4538 | F45: =-IS!E13 -> -4812 | G45: =G13*G41 -> -5195.0094 | H45: =H13*H41 -> -5538.1398 | I45: =I13*I41 -> -5909.6659 | J45: =J13*J41 -> -6312.2323 | K45: =K13*K41 -> -6748.7548
B46: Gross Profit | D46: =SUM(D42:D45) -> 3826 | E46: =SUM(E42:E45) -> 3779 | F46: =SUM(F42:F45) -> 4193 | G46: =SUM(G42:G45) -> 4424.5024 | H46: =SUM(H42:H45) -> 4697.6546 | I46: =SUM(I42:I45) -> 5006.0313 | J46: =SUM(J42:J45) -> 5338.3175 | K46: =SUM(K42:K45) -> 5696.5943
B48: S&GA R&D | D48: =-SUM(IS!C15,IS!C14) -> -1973 | E48: =-(IS!D14+IS!D15) -> -2076 | F48: =-(IS!E14+IS!E15) -> -2107 | G48: =G14*G42 -> -2330.1627 | H48: =H14*H42 -> -2467.4411 | I48: =I14*I42 -> -2627.075 | J48: =J14*J42 -> -2798.43 | K48: =K14*K42 -> -2982.4635
B49: Operating Profit | D49: =SUM(D46:D48) -> 1853 | E49: =SUM(E46:E48) -> 1703 | F49: =SUM(F46:F48) -> 2086 | G49: =SUM(G46:G48) -> 2094.3396 | H49: =SUM(H46:H48) -> 2230.2135 | I49: =SUM(I46:I48) -> 2378.9563 | J49: =SUM(J46:J48) -> 2539.8875 | K49: =SUM(K46:K48) -> 2714.1308
...
